<?xml version="1.0"?>
<robot name="mbot" xmlns:xacro="http://www.ros.org/wiki/xacro">

	<!-- PROPERTY LIST -->
	<xacro:property name="M_PI" value="3.1415926"/>
    <xacro:property name="base_length" value="0.034"/>
	<xacro:property name="base_radius" value="0.035"/>

	<xacro:property name="wheel_length" value="0.002"/>
    <xacro:property name="wheel_radius" value="0.02"/>
    <xacro:property name="wheel_joint_y" value="0.035"/>
    <xacro:property name="wheel_joint_z" value="0.02"/>

	<!-- Defining the colors used in this robot -->
	<material name="light_grey">
        <color rgba="0.8 0.8 0.8 0.5"/>
    </material>
	<material name="black">
        <color rgba="0.0 0.0 0.0 1"/>
    </material>
	<material name="green_pcb">
        <color rgba="0.23 0.4 0.16 1.0"/>
    </material>

	<!-- Macro for robot wheel -->
    <xacro:macro name="wheel" params="prefix reflect">
        <link name="${prefix}_wheel">
            <visual>
                <geometry>
                    <cylinder length = "${wheel_length}" radius="${wheel_radius}"/>
                </geometry>
				<origin rpy="0 ${M_PI/2} 0"/>
                <material name="black" />
            </visual>
        </link>

		<joint name="base_to_${prefix}_wheel" type="continuous">
            <parent link="base_link"/>
            <child link="${prefix}_wheel"/>
			<origin rpy="0 0 ${M_PI/2}" xyz="0 ${-reflect*wheel_joint_y} ${wheel_joint_z}"/>
        </joint>
    </xacro:macro>

	<xacro:macro name="puck_base">
        <link name="body_top">
            <visual>
                <geometry>
                	<cylinder length="0.002" radius="0.037"/>
            	</geometry>
            	<material name="green_pcb"/>
            </visual>
        </link>

        <joint name="base_to_body_top" type="fixed">
            <parent link="base_link"/>
        	<child link="body_top"/>
        	<origin xyz="0.0 0.0 0.037"/>
        </joint>

        <link name="base_link">
            <visual>
                <geometry>
                    <cylinder length="${base_length}" radius="${base_radius}"/>
                </geometry>
				<origin xyz="0.0 0.0 0.02"/>
                <material name="light_grey" />
            </visual>
        </link>

        <wheel prefix="left" reflect="-1"/>
        <wheel prefix="right" reflect="1"/>

    </xacro:macro>

</robot>